<?xml version="1.0"?>

<robot name="simple_robot"
       xmlns:xacro="http://www.ros.org/wiki/xacro">

  <xacro:property name="camera_height" value="1.0"/>

  <xacro:macro name="box_link" params="name size color">
    <link name="${name}">
      <visual>
        <geometry>
          <box size="${size}"/>
        </geometry>
        <material name="${name}_material">
          <color rgba="${color}"/>
        </material>
      </visual>
      
      <collision>
  	<geometry>
    	  <box size="${size}"/>
  	</geometry>
      </collision>

      <inertial>
        <mass value="1.0"/>
          <inertia
    	     ixx="0.01" ixy="0.0" ixz="0.0"
    	     iyy="0.01" iyz="0.0"
             izz="0.01"/>
      </inertial>
    </link>
  </xacro:macro>

  <xacro:box_link
    name="base_link"
    size="0.5 0.3 0.1"
    color="0 0 1 1"/>
  
  <xacro:box_link
    name="arm_link_1"
    size="0.1 0.1 0.6"
    color="0 1 0 1"/>
    
  <xacro:box_link
    name="arm_link_2"
    size="0.1 0.1 0.5"
    color="1 1 0 1"/>

  <xacro:box_link
    name="camera_link"
    size="0.1 0.1 0.1"
    color="1 0 0 1"/>

  <joint name="base_to_arm_joint" type="revolute">
    <parent link="base_link"/>
    <child link="arm_link_1"/>
    <origin xyz="0 0 0.35" rpy="0 0 0"/>
    <axis xyz="0 0 1"/>
    <limit lower="-1.57" upper="1.57" effort="10" velocity="1.0"/>
  </joint>
  
  <joint name="arm1_to_arm2_joint" type="revolute">
    <parent link="arm_link_1"/>
    <child link="arm_link_2"/>

    <origin xyz="0 0 0.55" rpy="0 0 0"/>

    <axis xyz="0 1 0"/>

    <limit lower="-1.57"
         upper="1.57"
         effort="10"
         velocity="1.0"/>
  </joint>

  <joint name="arm2_to_camera_joint" type="fixed">
    <parent link="arm_link_2"/>
    <child link="camera_link"/>
    <origin xyz="0 0 0.4" rpy="0 0 0"/>
  </joint>

</robot>
